<!-- |
     |  This document was autogenerated by xacro from ssafy_ws/src/urdf_practice/urdf/two_link_robot.xacro
     |  EDITING THIS FILE BY HAND IS NOT RECOMMENDED
     |  =============================================================================================== |
-->

<robot name="two_link_robot">

  <link name="base_link">
    <visual>
      <origin xyz="0 0 0"/>
      <geometry>
        <box size="1 1 1"/>
      </geometry>
    </visual>
  </link>

  <joint name="joint1" type="revolute">
    <parent link="base_link"/>
    <child link="second_link"/>
    <origin rpy="0 0 0" xyz="0 0 0.5"/>
    <axis xyz="1 0 0"/>
    <limit effort="1000" lower="-1.57" upper="1.57" velocity="1.0"/>
    # effort maximum torque, velocity max speed
  </joint>

  <link name="second_link">
    <visual>
      <origin rpy="0 0 0" xyz="0 0 0.5"/>
      <geometry>
        <cylinder length="1.0" radius="0.1"/>
      </geometry>
    </visual>
  </link>

</robot>
